[2023-08-25T10:45:53.496+0000] {taskinstance.py:1159} INFO - Dependencies all met for dep_context=non-requeueable deps ti=<TaskInstance: jinja_sql_dag.incremental_insert_task scheduled__2023-08-24T10:44:49.508666+00:00 [queued]>
[2023-08-25T10:45:53.501+0000] {taskinstance.py:1159} INFO - Dependencies all met for dep_context=requeueable deps ti=<TaskInstance: jinja_sql_dag.incremental_insert_task scheduled__2023-08-24T10:44:49.508666+00:00 [queued]>
[2023-08-25T10:45:53.502+0000] {taskinstance.py:1361} INFO - Starting attempt 2 of 3
[2023-08-25T10:45:53.509+0000] {taskinstance.py:1382} INFO - Executing <Task(PostgresOperator): incremental_insert_task> on 2023-08-24 10:44:49.508666+00:00
[2023-08-25T10:45:53.513+0000] {standard_task_runner.py:57} INFO - Started process 425 to run task
[2023-08-25T10:45:53.516+0000] {standard_task_runner.py:84} INFO - Running: ['***', 'tasks', 'run', 'jinja_sql_dag', 'incremental_insert_task', 'scheduled__2023-08-24T10:44:49.508666+00:00', '--job-id', '57', '--raw', '--subdir', 'DAGS_FOLDER/6_jinja/jinja_dev.py', '--cfg-path', '/tmp/tmpj_h067v9']
[2023-08-25T10:45:53.517+0000] {standard_task_runner.py:85} INFO - Job 57: Subtask incremental_insert_task
[2023-08-25T10:45:53.555+0000] {task_command.py:415} INFO - Running <TaskInstance: jinja_sql_dag.incremental_insert_task scheduled__2023-08-24T10:44:49.508666+00:00 [running]> on host 83fdf19a2df8
[2023-08-25T10:45:53.602+0000] {taskinstance.py:1660} INFO - Exporting env vars: AIRFLOW_CTX_DAG_OWNER='***' AIRFLOW_CTX_DAG_ID='jinja_sql_dag' AIRFLOW_CTX_TASK_ID='incremental_insert_task' AIRFLOW_CTX_EXECUTION_DATE='2023-08-24T10:44:49.508666+00:00' AIRFLOW_CTX_TRY_NUMBER='2' AIRFLOW_CTX_DAG_RUN_ID='scheduled__2023-08-24T10:44:49.508666+00:00'
[2023-08-25T10:45:53.603+0000] {sql.py:274} INFO - Executing: 
        INSERT INTO final_destination
        SELECT * FROM public.sales
        WHERE load_date = '2023-08-24'
        ON CONFLICT (rank_game, load_date) DO NOTHING;
    
[2023-08-25T10:45:53.618+0000] {taskinstance.py:1943} ERROR - Task failed with exception
Traceback (most recent call last):
  File "/home/airflow/.local/lib/python3.8/site-packages/airflow/providers/common/sql/operators/sql.py", line 275, in execute
    hook = self.get_db_hook()
  File "/home/airflow/.local/lib/python3.8/site-packages/airflow/providers/common/sql/operators/sql.py", line 186, in get_db_hook
    return self._hook
  File "/usr/local/lib/python3.8/functools.py", line 967, in __get__
    val = self.func(instance)
  File "/home/airflow/.local/lib/python3.8/site-packages/airflow/providers/common/sql/operators/sql.py", line 148, in _hook
    conn = BaseHook.get_connection(conn_id)
  File "/home/airflow/.local/lib/python3.8/site-packages/airflow/hooks/base.py", line 72, in get_connection
    conn = Connection.get_connection_from_secrets(conn_id)
  File "/home/airflow/.local/lib/python3.8/site-packages/airflow/models/connection.py", line 477, in get_connection_from_secrets
    raise AirflowNotFoundException(f"The conn_id `{conn_id}` isn't defined")
airflow.exceptions.AirflowNotFoundException: The conn_id `my_postgres_conn` isn't defined
[2023-08-25T10:45:53.621+0000] {taskinstance.py:1400} INFO - Marking task as UP_FOR_RETRY. dag_id=jinja_sql_dag, task_id=incremental_insert_task, execution_date=20230824T104449, start_date=20230825T104553, end_date=20230825T104553
[2023-08-25T10:45:53.629+0000] {standard_task_runner.py:104} ERROR - Failed to execute job 57 for task incremental_insert_task (The conn_id `my_postgres_conn` isn't defined; 425)
[2023-08-25T10:45:53.649+0000] {local_task_job_runner.py:228} INFO - Task exited with return code 1
[2023-08-25T10:45:53.665+0000] {taskinstance.py:2784} INFO - 0 downstream tasks scheduled from follow-on schedule check
