[2023-08-09T04:27:39.205+0000] {taskinstance.py:1103} INFO - Dependencies all met for dep_context=non-requeueable deps ti=<TaskInstance: taskflow_dag.create_txt_file__1 manual__2023-08-09T04:27:35.671519+00:00 [queued]>
[2023-08-09T04:27:39.212+0000] {taskinstance.py:1103} INFO - Dependencies all met for dep_context=requeueable deps ti=<TaskInstance: taskflow_dag.create_txt_file__1 manual__2023-08-09T04:27:35.671519+00:00 [queued]>
[2023-08-09T04:27:39.213+0000] {taskinstance.py:1308} INFO - Starting attempt 1 of 1
[2023-08-09T04:27:39.221+0000] {taskinstance.py:1327} INFO - Executing <Task(_PythonDecoratedOperator): create_txt_file__1> on 2023-08-09 04:27:35.671519+00:00
[2023-08-09T04:27:39.225+0000] {standard_task_runner.py:57} INFO - Started process 6745 to run task
[2023-08-09T04:27:39.229+0000] {standard_task_runner.py:84} INFO - Running: ['***', 'tasks', 'run', 'taskflow_dag', 'create_txt_file__1', 'manual__2023-08-09T04:27:35.671519+00:00', '--job-id', '82', '--raw', '--subdir', 'DAGS_FOLDER/5_taskflow_api/taskflow_dag.py', '--cfg-path', '/tmp/tmp6wqkn885']
[2023-08-09T04:27:39.231+0000] {standard_task_runner.py:85} INFO - Job 82: Subtask create_txt_file__1
[2023-08-09T04:27:39.275+0000] {task_command.py:410} INFO - Running <TaskInstance: taskflow_dag.create_txt_file__1 manual__2023-08-09T04:27:35.671519+00:00 [running]> on host ce583f477705
[2023-08-09T04:27:39.350+0000] {taskinstance.py:1547} INFO - Exporting env vars: AIRFLOW_CTX_DAG_OWNER='Willis' AIRFLOW_CTX_DAG_ID='taskflow_dag' AIRFLOW_CTX_TASK_ID='create_txt_file__1' AIRFLOW_CTX_EXECUTION_DATE='2023-08-09T04:27:35.671519+00:00' AIRFLOW_CTX_TRY_NUMBER='1' AIRFLOW_CTX_DAG_RUN_ID='manual__2023-08-09T04:27:35.671519+00:00'
[2023-08-09T04:27:39.351+0000] {taskinstance.py:1824} ERROR - Task failed with exception
Traceback (most recent call last):
  File "/home/airflow/.local/lib/python3.7/site-packages/airflow/decorators/base.py", line 220, in execute
    return_value = super().execute(context)
  File "/home/airflow/.local/lib/python3.7/site-packages/airflow/operators/python.py", line 181, in execute
    return_value = self.execute_callable()
  File "/home/airflow/.local/lib/python3.7/site-packages/airflow/operators/python.py", line 198, in execute_callable
    return self.python_callable(*self.op_args, **self.op_kwargs)
  File "/opt/airflow/dags/5_taskflow_api/taskflow_dag.py", line 51, in create_txt_file
    with open('/opt/airflow/dags/5_taskflow/sample_taskflow.txt', 'w') as file:
FileNotFoundError: [Errno 2] No such file or directory: '/opt/airflow/dags/5_taskflow/sample_taskflow.txt'
[2023-08-09T04:27:39.362+0000] {taskinstance.py:1350} INFO - Marking task as FAILED. dag_id=taskflow_dag, task_id=create_txt_file__1, execution_date=20230809T042735, start_date=20230809T042739, end_date=20230809T042739
[2023-08-09T04:27:39.370+0000] {standard_task_runner.py:109} ERROR - Failed to execute job 82 for task create_txt_file__1 ([Errno 2] No such file or directory: '/opt/airflow/dags/5_taskflow/sample_taskflow.txt'; 6745)
[2023-08-09T04:27:39.400+0000] {local_task_job_runner.py:225} INFO - Task exited with return code 1
[2023-08-09T04:27:39.416+0000] {taskinstance.py:2653} INFO - 0 downstream tasks scheduled from follow-on schedule check
